<?xml version="1.0" ?>
<!-- =================================================================================== -->
<!-- |    This document was autogenerated by xacro from robot_urdf.xacro               | -->
<!-- |    EDITING THIS FILE BY HAND IS NOT RECOMMENDED                                 | -->
<!-- =================================================================================== -->
<robot name="obot">
  <!-- Specify some standard inertial calculations https://en.wikipedia.org/wiki/List_of_moments_of_inertia -->
  <!-- These make use of xacro's mathematical functionality -->
  <!-- ################### inertia macros  ############################-->
  <!-- ###################################################################################### -->
  <!--  ########################### -->
  <!-- <xacro:macro name="material_blue">
        <material name="blue">
        <color rgba="0.2 0.2 1 1"/>
    </material>
    </xacro:macro> -->
  <!-- BASE LINK -->
  <!-- <base joint/> -->
  <link name="base_link">  
    </link>
  <!-- ################# -->
  <!-- CHASSIS LINK -->
  <joint name="chassis_joint" type="fixed">
    <parent link="base_link"/>
    <child link="chassis"/>
    <origin xyz="0 0 0.034"/>
  </joint>
  <link name="chassis">
    <visual>
      <origin rpy="0 0 0" xyz="0 0 0"/>
      <geometry>
        <cylinder length="0.005" radius="0.13"/>
      </geometry>
      <material name="orange">
        <color rgba="1 0.5 0 1"/>
      </material>
    </visual>
    <visual>
      <origin rpy="0 0 0" xyz="0 0 0.06"/>
      <geometry>
        <cylinder length="0.005" radius="0.13"/>
      </geometry>
      <material name="orange">
        <color rgba="1 0.5 0 1"/>
      </material>
    </visual>
    <visual>
      <origin rpy="0 0 0" xyz="0 0 0.12"/>
      <geometry>
        <cylinder length="0.005" radius="0.13"/>
      </geometry>
      <material name="orange">
        <color rgba="1 0.5 0 1"/>
      </material>
    </visual>
    <visual>
      <origin rpy="0 0 0" xyz="0.065 0.065 0.06"/>
      <geometry>
        <cylinder length="0.12" radius="0.005"/>
      </geometry>
      <material name="red">
        <color rgba="1 0 0 1"/>
      </material>
    </visual>
    <visual>
      <origin rpy="0 0 0" xyz="0.065 -0.065 0.06"/>
      <geometry>
        <cylinder length="0.12" radius="0.005"/>
      </geometry>
      <material name="red">
        <color rgba="1 0 0 1"/>
      </material>
    </visual>
    <visual>
      <origin rpy="0 0 0" xyz="-0.065 0.065 0.06"/>
      <geometry>
        <cylinder length="0.12" radius="0.005"/>
      </geometry>
      <material name="red">
        <color rgba="1 0 0 1"/>
      </material>
    </visual>
    <visual>
      <origin rpy="0 0 0" xyz="-0.065 -0.065 0.06"/>
      <geometry>
        <cylinder length="0.12" radius="0.005"/>
      </geometry>
      <material name="red">
        <color rgba="1 0 0 1"/>
      </material>
    </visual>
    <collision>
      <origin rpy="0 0 0" xyz="0 0 0.06"/>
      <geometry>
        <cylinder length="0.12" radius="0.13"/>
      </geometry>
    </collision>
    <inertial>
      <origin rpy="0 0 0" xyz="-0.08666666666666667 0 0"/>
      <mass value="2.0"/>
      <inertia ixx="0.008454166666666665" ixy="0.0" ixz="0.0" iyy="0.008454166666666665" iyz="0.0" izz="0.016900000000000002"/>
    </inertial>
  </link>
  <!--  ########################### -->
  <!-- LEFT DRIVE WHEEL -->
  <joint name="left_wheel_joint" type="continuous">
    <parent link="base_link"/>
    <child link="left_wheel"/>
    <origin rpy="-1.5707963267948966 0 0" xyz="0 0.11 0.034"/>
    <axis xyz="0 0 1"/>
  </joint>
  <link name="left_wheel">
    <visual>
      <origin rpy="0 0 0" xyz="0 0 0"/>
      <geometry>
        <cylinder length="0.026" radius="0.034"/>
      </geometry>
      <material name="black">
        <color rgba="0.025 0.025 0.025 1"/>
      </material>
    </visual>
    <collision>
      <origin rpy="0 0 0" xyz="0 0 0"/>
      <geometry>
        <cylinder length="0.026" radius="0.034"/>
        <!-- <sphere radius="${radius}"/> -->
      </geometry>
    </collision>
    <inertial>
      <origin rpy="0 0 0" xyz="0 0 0"/>
      <mass value="0.08"/>
      <inertia ixx="2.7626666666666664e-05" ixy="0.0" ixz="0.0" iyy="2.7626666666666664e-05" iyz="0.0" izz="4.6240000000000005e-05"/>
    </inertial>
  </link>
  <gazebo reference="left_wheel">
    <mu1>1.0</mu1>
    <mu2>1.0</mu2>
  </gazebo>
  <joint name="left_rim_joint" type="fixed">
    <parent link="left_wheel"/>
    <child link="left_rim"/>
    <origin rpy="0 0 0" xyz="0 0 0.001"/>
  </joint>
  <link name="left_rim">
    <visual>
      <origin rpy="0 0 0" xyz="0 0 0"/>
      <geometry>
        <box size="0.005 0.0408 0.026"/>
      </geometry>
      <material name="red">
        <color rgba="1 0 0 1"/>
      </material>
    </visual>
    <visual>
      <origin rpy="0 0 1.5707963267948966" xyz="0 0 0"/>
      <geometry>
        <box size="0.005 0.0408 0.026"/>
      </geometry>
      <material name="red">
        <color rgba="1 0 0 1"/>
      </material>
    </visual>
    <visual>
      <origin rpy="0 0 -0.7853981633974483" xyz="0 0 0"/>
      <geometry>
        <box size="0.005 0.0408 0.026"/>
      </geometry>
      <material name="red">
        <color rgba="1 0 0 1"/>
      </material>
    </visual>
    <visual>
      <origin rpy="0 0 0.7853981633974483" xyz="0 0 0"/>
      <geometry>
        <box size="0.005 0.0408 0.026"/>
      </geometry>
      <material name="red">
        <color rgba="1 0 0 1"/>
      </material>
    </visual>
  </link>
  <!-- ############################# -->
  <!-- RIGHT DRIVE WHEEL -->
  <joint name="right_wheel_joint" type="continuous">
    <parent link="base_link"/>
    <child link="right_wheel"/>
    <origin rpy="-1.5707963267948966 0 0" xyz="0 -0.11 0.034"/>
    <axis xyz="0 0 1"/>
  </joint>
  <link name="right_wheel">
    <visual>
      <origin rpy="0 0 0" xyz="0 0 0"/>
      <geometry>
        <cylinder length="0.026" radius="0.034"/>
      </geometry>
      <material name="black">
        <color rgba="0.025 0.025 0.025 1"/>
      </material>
    </visual>
    <collision>
      <origin rpy="0 0 0" xyz="0 0 0"/>
      <geometry>
        <cylinder length="0.026" radius="0.034"/>
        <!-- <sphere radius="${radius}"/> -->
      </geometry>
    </collision>
    <inertial>
      <origin rpy="0 0 0" xyz="0 0 0"/>
      <mass value="0.08"/>
      <inertia ixx="2.7626666666666664e-05" ixy="0.0" ixz="0.0" iyy="2.7626666666666664e-05" iyz="0.0" izz="4.6240000000000005e-05"/>
    </inertial>
  </link>
  <gazebo reference="right_wheel">
    <mu1>1.0</mu1>
    <mu2>1.0</mu2>
  </gazebo>
  <joint name="right_rim_joint" type="fixed">
    <parent link="right_wheel"/>
    <child link="right_rim"/>
    <origin rpy="0 0 0" xyz="0 0 -0.001"/>
  </joint>
  <link name="right_rim">
    <visual>
      <origin rpy="0 0 0" xyz="0 0 0"/>
      <geometry>
        <box size="0.005 0.0408 0.026"/>
      </geometry>
      <material name="red">
        <color rgba="1 0 0 1"/>
      </material>
    </visual>
    <visual>
      <origin rpy="0 0 1.5707963267948966" xyz="0 0 0"/>
      <geometry>
        <box size="0.005 0.0408 0.026"/>
      </geometry>
      <material name="red">
        <color rgba="1 0 0 1"/>
      </material>
    </visual>
    <visual>
      <origin rpy="0 0 -0.7853981633974483" xyz="0 0 0"/>
      <geometry>
        <box size="0.005 0.0408 0.026"/>
      </geometry>
      <material name="red">
        <color rgba="1 0 0 1"/>
      </material>
    </visual>
    <visual>
      <origin rpy="0 0 0.7853981633974483" xyz="0 0 0"/>
      <geometry>
        <box size="0.005 0.0408 0.026"/>
      </geometry>
      <material name="red">
        <color rgba="1 0 0 1"/>
      </material>
    </visual>
  </link>
  <!-- ############################# -->
  <!--  castor WHEEL LINK -->
  <joint name="castor_wheel_joint" type="fixed">
    <parent link="base_link"/>
    <child link="castor_wheel"/>
    <origin xyz="-0.08666666666666667 0 0.017"/>
  </joint>
  <link name="castor_wheel">
    <visual>
      <origin rpy="0 0 0" xyz="0 0 0"/>
      <geometry>
        <sphere radius="0.017"/>
      </geometry>
      <material name="silver">
        <color rgba="0.5 0.5 0.5 1"/>
      </material>
    </visual>
    <collision>
      <origin rpy="0 0 0" xyz="0 0 0"/>
      <geometry>
        <sphere radius="0.017"/>
      </geometry>
    </collision>
    <inertial>
      <origin rpy="0 0 0" xyz="0 0 0"/>
      <mass value="0.04"/>
      <inertia ixx="4.624000000000001e-06" ixy="0.0" ixz="0.0" iyy="4.624000000000001e-06" iyz="0.0" izz="4.624000000000001e-06"/>
    </inertial>
  </link>
  <gazebo reference="castor_wheel">
    <mu1>0.001</mu1>
    <mu2>0.001</mu2>
  </gazebo>
  <!--  ########################### -->
  <joint name="sonar_front_joint" type="fixed">
    <parent link="chassis"/>
    <child link="sonar_front"/>
    <origin rpy="0 0 0" xyz="0.13 0 0.06999999999999999"/>
  </joint>
  <link name="sonar_front">
    <visual>
      <origin rpy="0 1.5707963267948966 0" xyz="0 0.01 0"/>
      <geometry>
        <cylinder length="0.006" radius="0.006"/>
      </geometry>
      <material name="blue">
        <color rgba="0.2 0.2 1 1"/>
      </material>
    </visual>
    <collision>
      <origin rpy="0 1.5707963267948966 0" xyz="0 0.01 0"/>
      <geometry>
        <cylinder length="0.006" radius="0.006"/>
      </geometry>
    </collision>
    <visual>
      <origin rpy="0 1.5707963267948966 0" xyz="0 -0.01 0"/>
      <geometry>
        <cylinder length="0.006" radius="0.006"/>
      </geometry>
      <material name="blue">
        <color rgba="0.2 0.2 1 1"/>
      </material>
    </visual>
    <collision>
      <origin rpy="0 1.5707963267948966 0" xyz="0 -0.01 0"/>
      <geometry>
        <cylinder length="0.006" radius="0.006"/>
      </geometry>
    </collision>
    <inertial>
      <origin rpy="0 1.5707963267948966 0" xyz="0 0.01 0"/>
      <mass value="0.005"/>
      <inertia ixx="6e-08" ixy="0.0" ixz="0.0" iyy="6e-08" iyz="0.0" izz="9e-08"/>
    </inertial>
  </link>
  <joint name="sonar_left_joint" type="fixed">
    <parent link="chassis"/>
    <child link="sonar_left"/>
    <origin rpy="0.0 0.0 0.7853981633974483" xyz="0.09192299999999999 0.09192299999999999 0.06999999999999999"/>
  </joint>
  <link name="sonar_left">
    <visual>
      <origin rpy="0 1.5707963267948966 0" xyz="0 0.01 0"/>
      <geometry>
        <cylinder length="0.006" radius="0.006"/>
      </geometry>
      <material name="blue">
        <color rgba="0.2 0.2 1 1"/>
      </material>
    </visual>
    <collision>
      <origin rpy="0 1.5707963267948966 0" xyz="0 0.01 0"/>
      <geometry>
        <cylinder length="0.006" radius="0.006"/>
      </geometry>
    </collision>
    <visual>
      <origin rpy="0 1.5707963267948966 0" xyz="0 -0.01 0"/>
      <geometry>
        <cylinder length="0.006" radius="0.006"/>
      </geometry>
      <material name="blue">
        <color rgba="0.2 0.2 1 1"/>
      </material>
    </visual>
    <collision>
      <origin rpy="0 1.5707963267948966 0" xyz="0 -0.01 0"/>
      <geometry>
        <cylinder length="0.006" radius="0.006"/>
      </geometry>
    </collision>
    <inertial>
      <origin rpy="0 1.5707963267948966 0" xyz="0 0.01 0"/>
      <mass value="0.005"/>
      <inertia ixx="6e-08" ixy="0.0" ixz="0.0" iyy="6e-08" iyz="0.0" izz="9e-08"/>
    </inertial>
  </link>
  <joint name="sonar_right_joint" type="fixed">
    <parent link="chassis"/>
    <child link="sonar_right"/>
    <origin rpy="0.0 0.0 -0.7853981633974483" xyz="0.09192299999999999 -0.09192299999999999 0.06999999999999999"/>
  </joint>
  <link name="sonar_right">
    <visual>
      <origin rpy="0 1.5707963267948966 0" xyz="0 0.01 0"/>
      <geometry>
        <cylinder length="0.006" radius="0.006"/>
      </geometry>
      <material name="blue">
        <color rgba="0.2 0.2 1 1"/>
      </material>
    </visual>
    <collision>
      <origin rpy="0 1.5707963267948966 0" xyz="0 0.01 0"/>
      <geometry>
        <cylinder length="0.006" radius="0.006"/>
      </geometry>
    </collision>
    <visual>
      <origin rpy="0 1.5707963267948966 0" xyz="0 -0.01 0"/>
      <geometry>
        <cylinder length="0.006" radius="0.006"/>
      </geometry>
      <material name="blue">
        <color rgba="0.2 0.2 1 1"/>
      </material>
    </visual>
    <collision>
      <origin rpy="0 1.5707963267948966 0" xyz="0 -0.01 0"/>
      <geometry>
        <cylinder length="0.006" radius="0.006"/>
      </geometry>
    </collision>
    <inertial>
      <origin rpy="0 1.5707963267948966 0" xyz="0 0.01 0"/>
      <mass value="0.005"/>
      <inertia ixx="6e-08" ixy="0.0" ixz="0.0" iyy="6e-08" iyz="0.0" izz="9e-08"/>
    </inertial>
  </link>
  <joint name="lidar_joint" type="fixed">
    <parent link="chassis"/>
    <child link="lidar"/>
    <origin rpy="0 0 0" xyz="0 0 0.16"/>
  </joint>
  <link name="lidar">
    <visual>
      <origin xyz="0 0 -0.02"/>
      <geometry>
        <cylinder length="0.04" radius="0.03"/>
      </geometry>
      <material name="black">
        <color rgba="0.025 0.025 0.025 1"/>
      </material>
    </visual>
    <collision>
      <origin xyz="0 0 -0.02"/>
      <geometry>
        <cylinder length="0.04" radius="0.03"/>
      </geometry>
    </collision>
    <inertial>
      <origin rpy="0 0 0" xyz="0 0 -0.02"/>
      <mass value="0.1"/>
      <inertia ixx="3.5833333333333335e-05" ixy="0.0" ixz="0.0" iyy="3.5833333333333335e-05" iyz="0.0" izz="4.5e-05"/>
    </inertial>
  </link>
  <gazebo reference="lidar">
    <sensor name="lidar" type="gpu_lidar">
      <pose>0 0 0 0 0 0</pose>
      <topic>lidar</topic>
      <update_rate>10</update_rate>
      <ray>
        <scan>
          <horizontal>
            <samples>360</samples>
            <min_angle>-6.283185307179586</min_angle>
            <max_angle>6.283185307179586</max_angle>
            <resolution>0.5</resolution>
          </horizontal>
          <vertical>
            <samples>1</samples>
            <resolution>0.01</resolution>
            <min_angle>0</min_angle>
            <max_angle>0</max_angle>
          </vertical>
        </scan>
        <range>
          <min>0.1</min>
          <max>10</max>
          <resolution>0.01</resolution>
        </range>
      </ray>
      <always_on>1</always_on>
      <visualize>False</visualize>
    </sensor>
  </gazebo>
  <joint name="imu_joint" type="fixed">
    <parent link="chassis"/>
    <child link="imu"/>
    <origin rpy="0 0 0" xyz="0 0 0.06"/>
  </joint>
  <link name="imu"/>
  <gazebo reference="imu">
    <sensor name="imu" type="imu">
      <always_on>1</always_on>
      <update_rate>1</update_rate>
      <visualize>true</visualize>
      <topic>imu</topic>
    </sensor>
  </gazebo>
  <joint name="camera_joint" type="fixed">
    <parent link="chassis"/>
    <child link="camera"/>
    <origin rpy="0 0 0" xyz="0.17 0 0.12"/>
  </joint>
  <link name="camera">
    <visual>
      <origin rpy="0 -1.5707963267948966 0" xyz="-0.02 0 0"/>
      <geometry>
        <cylinder length="0.04" radius="0.015"/>
      </geometry>
      <material name="black">
        <color rgba="0.025 0.025 0.025 1"/>
      </material>
    </visual>
    <visual>
      <origin rpy="0 -1.5707963267948966 0" xyz="-0.03 0 0"/>
      <geometry>
        <!-- <cylinder radius="0.03" length="0.02"/> -->
        <box size="0.04 0.06 0.02"/>
      </geometry>
      <material name="black">
        <color rgba="0.025 0.025 0.025 1"/>
      </material>
    </visual>
    <collision>
      <origin rpy="0 -1.5707963267948966 0" xyz="-0.02 0 0"/>
      <geometry>
        <cylinder length="0.04" radius="0.02"/>
      </geometry>
    </collision>
    <inertial>
      <origin rpy="0 -1.5707963267948966 0" xyz="-0.02 0 0"/>
      <mass value="0.005"/>
      <inertia ixx="1.1666666666666666e-06" ixy="0.0" ixz="0.0" iyy="1.1666666666666666e-06" iyz="0.0" izz="1.0000000000000002e-06"/>
    </inertial>
  </link>
  <joint name="camera_optical_joint" type="fixed">
    <parent link="camera"/>
    <child link="camera_optical_link"/>
    <origin rpy="-1.5707963267948966 0 -1.5707963267948966" xyz="0 0 0"/>
  </joint>
  <link name="camera_optical_link"/>
  <gazebo>
    <plugin filename="ignition-gazebo-diff-drive-system" name="ignition::gazebo::systems::DiffDrive">
      <left_joint>left_wheel_joint</left_joint>
      <right_joint>right_wheel_joint</right_joint>
      <wheel_separation>0.22</wheel_separation>
      <wheel_radius>0.034</wheel_radius>
      <max_linear_acceleration>5</max_linear_acceleration>
      <min_linear_acceleration>-5</min_linear_acceleration>
      <max_angular_acceleration>10</max_angular_acceleration>
      <min_angular_acceleration>-10</min_angular_acceleration>
      <max_linear_velocity>0.5</max_linear_velocity>
      <min_linear_velocity>-0.5</min_linear_velocity>
      <max_angular_velocity>1.5</max_angular_velocity>
      <min_angular_velocity>-1.5</min_angular_velocity>
    </plugin>
  </gazebo>
</robot>
<!-- xacro robot_urdf.xacro > _robot.urdf -->
