<sdf version='1.7'>
  <model name='obot'>
    <link name='base_link'>
      <inertial>
        <pose>-0.080778 5.6e-05 0.040931 0 -0 0</pose>
        <mass>2.16</mass>
        <inertia>
          <ixx>0.0105947</ixx>
          <ixy>-1.62508e-05</ixy>
          <ixz>-0.00146803</ixz>
          <iyy>0.0120197</iyy>
          <iyz>-7.61316e-06</iyz>
          <izz>0.0185469</izz>
        </inertia>
      </inertial>
      <collision name='base_link_fixed_joint_lump__castor_wheel_collision'>
        <pose>-0.086667 0 0.017 0 -0 0</pose>
        <geometry>
          <sphere>
            <radius>0.017</radius>
          </sphere>
        </geometry>
        <surface>
          <contact>
            <ode/>
          </contact>
          <friction>
            <ode>
              <mu>0.001</mu>
              <mu2>0.001</mu2>
            </ode>
          </friction>
        </surface>
      </collision>
      <collision name='base_link_fixed_joint_lump__chassis_collision_1'>
        <pose>0 0 0.094 0 -0 0</pose>
        <geometry>
          <cylinder>
            <length>0.12</length>
            <radius>0.13</radius>
          </cylinder>
        </geometry>
      </collision>
      <collision name='base_link_fixed_joint_lump__camera_collision_2'>
        <pose>0.15 0 0.154 0 -1.5708 0</pose>
        <geometry>
          <cylinder>
            <length>0.04</length>
            <radius>0.02</radius>
          </cylinder>
        </geometry>
      </collision>
      <collision name='base_link_fixed_joint_lump__lidar_collision_3'>
        <pose>0 0 0.174 0 -0 0</pose>
        <geometry>
          <cylinder>
            <length>0.04</length>
            <radius>0.03</radius>
          </cylinder>
        </geometry>
        <surface>
          <contact>
            <ode/>
          </contact>
          <friction>
            <ode/>
          </friction>
        </surface>
      </collision>
      <collision name='base_link_fixed_joint_lump__sonar_front_collision_4'>
        <pose>0.13 0.01 0.104 0 1.5708 0</pose>
        <geometry>
          <cylinder>
            <length>0.006</length>
            <radius>0.006</radius>
          </cylinder>
        </geometry>
      </collision>
      <collision name='base_link_fixed_joint_lump__sonar_front_collision_5'>
        <pose>0.13 -0.01 0.104 0 1.5708 0</pose>
        <geometry>
          <cylinder>
            <length>0.006</length>
            <radius>0.006</radius>
          </cylinder>
        </geometry>
      </collision>
      <collision name='base_link_fixed_joint_lump__sonar_left_collision_6'>
        <pose>0.084852 0.098994 0.104 -0.785398 1.5708 0</pose>
        <geometry>
          <cylinder>
            <length>0.006</length>
            <radius>0.006</radius>
          </cylinder>
        </geometry>
      </collision>
      <collision name='base_link_fixed_joint_lump__sonar_left_collision_7'>
        <pose>0.098994 0.084852 0.104 -0.785398 1.5708 0</pose>
        <geometry>
          <cylinder>
            <length>0.006</length>
            <radius>0.006</radius>
          </cylinder>
        </geometry>
      </collision>
      <collision name='base_link_fixed_joint_lump__sonar_right_collision_8'>
        <pose>0.098994 -0.084852 0.104 0.785398 1.5708 0</pose>
        <geometry>
          <cylinder>
            <length>0.006</length>
            <radius>0.006</radius>
          </cylinder>
        </geometry>
      </collision>
      <collision name='base_link_fixed_joint_lump__sonar_right_collision_9'>
        <pose>0.084852 -0.098994 0.104 0.785398 1.5708 0</pose>
        <geometry>
          <cylinder>
            <length>0.006</length>
            <radius>0.006</radius>
          </cylinder>
        </geometry>
      </collision>
      <visual name='base_link_fixed_joint_lump__castor_wheel_visual'>
        <pose>-0.086667 0 0.017 0 -0 0</pose>
        <geometry>
          <sphere>
            <radius>0.017</radius>
          </sphere>
        </geometry>
      </visual>
      <visual name='base_link_fixed_joint_lump__chassis_visual_1'>
        <pose>0 0 0.034 0 -0 0</pose>
        <geometry>
          <cylinder>
            <length>0.005</length>
            <radius>0.13</radius>
          </cylinder>
        </geometry>
      </visual>
      <visual name='base_link_fixed_joint_lump__chassis_visual_2'>
        <pose>0 0 0.094 0 -0 0</pose>
        <geometry>
          <cylinder>
            <length>0.005</length>
            <radius>0.13</radius>
          </cylinder>
        </geometry>
      </visual>
      <visual name='base_link_fixed_joint_lump__chassis_visual_3'>
        <pose>0 0 0.154 0 -0 0</pose>
        <geometry>
          <cylinder>
            <length>0.005</length>
            <radius>0.13</radius>
          </cylinder>
        </geometry>
      </visual>
      <visual name='base_link_fixed_joint_lump__chassis_visual_4'>
        <pose>0.065 0.065 0.094 0 -0 0</pose>
        <geometry>
          <cylinder>
            <length>0.12</length>
            <radius>0.005</radius>
          </cylinder>
        </geometry>
      </visual>
      <visual name='base_link_fixed_joint_lump__chassis_visual_5'>
        <pose>0.065 -0.065 0.094 0 -0 0</pose>
        <geometry>
          <cylinder>
            <length>0.12</length>
            <radius>0.005</radius>
          </cylinder>
        </geometry>
      </visual>
      <visual name='base_link_fixed_joint_lump__chassis_visual_6'>
        <pose>-0.065 0.065 0.094 0 -0 0</pose>
        <geometry>
          <cylinder>
            <length>0.12</length>
            <radius>0.005</radius>
          </cylinder>
        </geometry>
      </visual>
      <visual name='base_link_fixed_joint_lump__chassis_visual_7'>
        <pose>-0.065 -0.065 0.094 0 -0 0</pose>
        <geometry>
          <cylinder>
            <length>0.12</length>
            <radius>0.005</radius>
          </cylinder>
        </geometry>
      </visual>
      <visual name='base_link_fixed_joint_lump__camera_visual_8'>
        <pose>0.15 0 0.154 0 -1.5708 0</pose>
        <geometry>
          <cylinder>
            <length>0.04</length>
            <radius>0.015</radius>
          </cylinder>
        </geometry>
      </visual>
      <visual name='base_link_fixed_joint_lump__camera_visual_9'>
        <pose>0.14 0 0.154 0 -1.5708 0</pose>
        <geometry>
          <box>
            <size>0.04 0.06 0.02</size>
          </box>
        </geometry>
      </visual>
      <visual name='base_link_fixed_joint_lump__lidar_visual_10'>
        <pose>0 0 0.174 0 -0 0</pose>
        <geometry>
          <cylinder>
            <length>0.04</length>
            <radius>0.03</radius>
          </cylinder>
        </geometry>
      </visual>
      <visual name='base_link_fixed_joint_lump__sonar_front_visual_11'>
        <pose>0.13 0.01 0.104 0 1.5708 0</pose>
        <geometry>
          <cylinder>
            <length>0.006</length>
            <radius>0.006</radius>
          </cylinder>
        </geometry>
      </visual>
      <visual name='base_link_fixed_joint_lump__sonar_front_visual_12'>
        <pose>0.13 -0.01 0.104 0 1.5708 0</pose>
        <geometry>
          <cylinder>
            <length>0.006</length>
            <radius>0.006</radius>
          </cylinder>
        </geometry>
      </visual>
      <visual name='base_link_fixed_joint_lump__sonar_left_visual_13'>
        <pose>0.084852 0.098994 0.104 -0.785398 1.5708 0</pose>
        <geometry>
          <cylinder>
            <length>0.006</length>
            <radius>0.006</radius>
          </cylinder>
        </geometry>
      </visual>
      <visual name='base_link_fixed_joint_lump__sonar_left_visual_14'>
        <pose>0.098994 0.084852 0.104 -0.785398 1.5708 0</pose>
        <geometry>
          <cylinder>
            <length>0.006</length>
            <radius>0.006</radius>
          </cylinder>
        </geometry>
      </visual>
      <visual name='base_link_fixed_joint_lump__sonar_right_visual_15'>
        <pose>0.098994 -0.084852 0.104 0.785398 1.5708 0</pose>
        <geometry>
          <cylinder>
            <length>0.006</length>
            <radius>0.006</radius>
          </cylinder>
        </geometry>
      </visual>
      <visual name='base_link_fixed_joint_lump__sonar_right_visual_16'>
        <pose>0.084852 -0.098994 0.104 0.785398 1.5708 0</pose>
        <geometry>
          <cylinder>
            <length>0.006</length>
            <radius>0.006</radius>
          </cylinder>
        </geometry>
      </visual>
      <sensor name='imu' type='imu'>
        <always_on>1</always_on>
        <update_rate>1</update_rate>
        <visualize>1</visualize>
        <topic>imu</topic>
        <pose>0 0 0.094 0 -0 0</pose>
      </sensor>
      <sensor name='lidar' type='gpu_lidar'>
        <topic>lidar</topic>
        <update_rate>10</update_rate>
        <ray>
          <scan>
            <horizontal>
              <samples>360</samples>
              <min_angle>-6.28319</min_angle>
              <max_angle>6.28319</max_angle>
              <resolution>0.5</resolution>
            </horizontal>
            <vertical>
              <samples>1</samples>
              <resolution>0.01</resolution>
              <min_angle>0</min_angle>
              <max_angle>0</max_angle>
            </vertical>
          </scan>
          <range>
            <min>0.1</min>
            <max>10</max>
            <resolution>0.01</resolution>
          </range>
        </ray>
        <always_on>1</always_on>
        <visualize>0</visualize>
        <pose>0 0 0.194 0 -0 0</pose>
      </sensor>
    </link>
    <joint name='left_wheel_joint' type='revolute'>
      <pose relative_to='base_link'>0 0.11 0.034 -1.5708 0 0</pose>
      <parent>base_link</parent>
      <child>left_wheel</child>
      <axis>
        <xyz>0 0 1</xyz>
        <limit>
          <lower>-1e+16</lower>
          <upper>1e+16</upper>
        </limit>
        <dynamics>
          <spring_reference>0</spring_reference>
          <spring_stiffness>0</spring_stiffness>
        </dynamics>
      </axis>
    </joint>
    <link name='left_wheel'>
      <pose relative_to='left_wheel_joint'>0 0 0 0 -0 0</pose>
      <inertial>
        <pose>0 0 0 0 -0 0</pose>
        <mass>0.08</mass>
        <inertia>
          <ixx>2.76267e-05</ixx>
          <ixy>0</ixy>
          <ixz>0</ixz>
          <iyy>2.76267e-05</iyy>
          <iyz>0</iyz>
          <izz>4.624e-05</izz>
        </inertia>
      </inertial>
      <collision name='left_wheel_collision'>
        <pose>0 0 0 0 -0 0</pose>
        <geometry>
          <cylinder>
            <length>0.026</length>
            <radius>0.034</radius>
          </cylinder>
        </geometry>
        <surface>
          <contact>
            <ode/>
          </contact>
          <friction>
            <ode>
              <mu>1</mu>
              <mu2>1</mu2>
            </ode>
          </friction>
        </surface>
      </collision>
      <visual name='left_wheel_visual'>
        <pose>0 0 0 0 -0 0</pose>
        <geometry>
          <cylinder>
            <length>0.026</length>
            <radius>0.034</radius>
          </cylinder>
        </geometry>
      </visual>
      <visual name='left_wheel_fixed_joint_lump__left_rim_visual_1'>
        <pose>0 0 0.001 0 -0 0</pose>
        <geometry>
          <box>
            <size>0.005 0.0408 0.026</size>
          </box>
        </geometry>
      </visual>
      <visual name='left_wheel_fixed_joint_lump__left_rim_visual_2'>
        <pose>0 0 0.001 0 -0 1.5708</pose>
        <geometry>
          <box>
            <size>0.005 0.0408 0.026</size>
          </box>
        </geometry>
      </visual>
      <visual name='left_wheel_fixed_joint_lump__left_rim_visual_3'>
        <pose>0 0 0.001 0 0 -0.785398</pose>
        <geometry>
          <box>
            <size>0.005 0.0408 0.026</size>
          </box>
        </geometry>
      </visual>
      <visual name='left_wheel_fixed_joint_lump__left_rim_visual_4'>
        <pose>0 0 0.001 0 -0 0.785398</pose>
        <geometry>
          <box>
            <size>0.005 0.0408 0.026</size>
          </box>
        </geometry>
      </visual>
    </link>
    <joint name='right_wheel_joint' type='revolute'>
      <pose relative_to='base_link'>0 -0.11 0.034 -1.5708 0 0</pose>
      <parent>base_link</parent>
      <child>right_wheel</child>
      <axis>
        <xyz>0 0 1</xyz>
        <limit>
          <lower>-1e+16</lower>
          <upper>1e+16</upper>
        </limit>
        <dynamics>
          <spring_reference>0</spring_reference>
          <spring_stiffness>0</spring_stiffness>
        </dynamics>
      </axis>
    </joint>
    <link name='right_wheel'>
      <pose relative_to='right_wheel_joint'>0 0 0 0 -0 0</pose>
      <inertial>
        <pose>0 0 0 0 -0 0</pose>
        <mass>0.08</mass>
        <inertia>
          <ixx>2.76267e-05</ixx>
          <ixy>0</ixy>
          <ixz>0</ixz>
          <iyy>2.76267e-05</iyy>
          <iyz>0</iyz>
          <izz>4.624e-05</izz>
        </inertia>
      </inertial>
      <collision name='right_wheel_collision'>
        <pose>0 0 0 0 -0 0</pose>
        <geometry>
          <cylinder>
            <length>0.026</length>
            <radius>0.034</radius>
          </cylinder>
        </geometry>
        <surface>
          <contact>
            <ode/>
          </contact>
          <friction>
            <ode>
              <mu>1</mu>
              <mu2>1</mu2>
            </ode>
          </friction>
        </surface>
      </collision>
      <visual name='right_wheel_visual'>
        <pose>0 0 0 0 -0 0</pose>
        <geometry>
          <cylinder>
            <length>0.026</length>
            <radius>0.034</radius>
          </cylinder>
        </geometry>
      </visual>
      <visual name='right_wheel_fixed_joint_lump__right_rim_visual_1'>
        <pose>0 0 -0.001 0 -0 0</pose>
        <geometry>
          <box>
            <size>0.005 0.0408 0.026</size>
          </box>
        </geometry>
      </visual>
      <visual name='right_wheel_fixed_joint_lump__right_rim_visual_2'>
        <pose>0 0 -0.001 0 -0 1.5708</pose>
        <geometry>
          <box>
            <size>0.005 0.0408 0.026</size>
          </box>
        </geometry>
      </visual>
      <visual name='right_wheel_fixed_joint_lump__right_rim_visual_3'>
        <pose>0 0 -0.001 0 0 -0.785398</pose>
        <geometry>
          <box>
            <size>0.005 0.0408 0.026</size>
          </box>
        </geometry>
      </visual>
      <visual name='right_wheel_fixed_joint_lump__right_rim_visual_4'>
        <pose>0 0 -0.001 0 -0 0.785398</pose>
        <geometry>
          <box>
            <size>0.005 0.0408 0.026</size>
          </box>
        </geometry>
      </visual>
    </link>
    <static>0</static>
    <plugin name='ignition::gazebo::systems::DiffDrive' filename='ignition-gazebo-diff-drive-system'>
      <left_joint>left_wheel_joint</left_joint>
      <right_joint>right_wheel_joint</right_joint>
      <wheel_separation>0.22</wheel_separation>
      <wheel_radius>0.034</wheel_radius>
      <max_linear_acceleration>5</max_linear_acceleration>
      <min_linear_acceleration>-5</min_linear_acceleration>
      <max_angular_acceleration>10</max_angular_acceleration>
      <min_angular_acceleration>-10</min_angular_acceleration>
      <max_linear_velocity>0.5</max_linear_velocity>
      <min_linear_velocity>-0.5</min_linear_velocity>
      <max_angular_velocity>1.5</max_angular_velocity>
      <min_angular_velocity>-1.5</min_angular_velocity>
    </plugin>
  </model>
</sdf>
